<!DOCTYPE html>
<html lang="en">
<head>
    <meta charset="UTF-8">
    <meta name="viewport" content="width=device-width, initial-scale=1.0">
    <title>JavaScript Error Handling</title>
    <style>
        body {
            font-family: Arial, sans-serif;
            margin: 20px;
            line-height: 1.6;
        }
        h1, h2 {
            color: #ba3e00;
        }
        code {
            display: block;
            background: #f4f4f4;
            padding: 10px;
            border: 1px solid #ddd;
            margin-bottom: 10px;
            white-space: pre;
            overflow-x: auto;
        }
        .error {
            background: #ffe6e6;
            border: 1px solid #ff4d4d;
            padding: 10px;
            margin-bottom: 10px;
        }
    </style>
</head>
<body>
    <h1>JavaScript Error Handling</h1>

    <h2>1. Try-Catch Blocks</h2>
    <p>The <code>try</code>-<code>catch</code> block is used to handle exceptions in JavaScript. Code that might throw an error is placed in the <code>try</code> block, and the <code>catch</code> block handles the error if it occurs.</p>
    <h3>Example: Basic Try-Catch</h3>
    <code>
try {
    const result = 10 / 0;
    console.log(result); // This doesn't throw an error (division by zero is Infinity)
    
    // Deliberate error
    console.log(nonExistentVariable); // ReferenceError: nonExistentVariable is not defined
} catch (error) {
    console.error("An error occurred:", error.message);
}
/* Output:
An error occurred: nonExistentVariable is not defined
*/
    </code>
    <p>In this example, the deliberate error triggers the <code>catch</code> block, and the error message is logged to the console.</p>

    <h3>Example: Catching Specific Errors</h3>
    <code>
try {
    JSON.parse("{ invalid JSON }"); // SyntaxError
} catch (error) {
    if (error instanceof SyntaxError) {
        console.error("Invalid JSON format:", error.message);
    } else {
        console.error("An unexpected error occurred:", error.message);
    }
}
/* Output:
Invalid JSON format: Unexpected token i in JSON at position 2
*/
    </code>
    <p>Using <code>instanceof</code>, you can handle specific types of errors (like <code>SyntaxError</code>) differently.</p>

    <h2>2. Throwing Errors</h2>
    <p>You can create and throw your own errors in JavaScript using the <code>throw</code> statement. This is useful for creating custom error messages or handling specific situations.</p>
    
    <h3>Example: Throwing a Custom Error</h3>
    <code>
function divide(a, b) {
    if (b === 0) {
        throw new Error("Division by zero is not allowed");
    }
    return a / b;
}

try {
    const result = divide(10, 0); // This will throw an error
    console.log(result);
} catch (error) {
    console.error("Error:", error.message);
}
/* Output:
Error: Division by zero is not allowed
*/
    </code>
    <p>In this example, a custom error is thrown when attempting to divide by zero, which is then caught and handled in the <code>catch</code> block.</p>

    <h3>Example: Re-Throwing Errors</h3>
    <code>
try {
    try {
        throw new Error("Something went wrong");
    } catch (error) {
        console.error("Caught an error:", error.message);
        // Re-throw the error
        throw error;
    }
} catch (error) {
    console.error("Error re-thrown and handled here:", error.message);
}
/* Output:
Caught an error: Something went wrong
Error re-thrown and handled here: Something went wrong
*/
    </code>
    <p>Errors can be re-thrown from a <code>catch</code> block if you need to propagate them to higher levels of the application.</p>

    <h2>3. Finally Block</h2>
    <p>The <code>finally</code> block contains code that runs regardless of whether an error was thrown or not. It's often used for cleanup tasks.</p>
    <h3>Example: Try-Catch-Finally</h3>
    <code>
try {
    console.log("Start of try block");
    throw new Error("An error occurred");
} catch (error) {
    console.error("Caught an error:", error.message);
} finally {
    console.log("This code runs no matter what");
}
/* Output:
Start of try block
Caught an error: An error occurred
This code runs no matter what
*/
    </code>
    <p>The <code>finally</code> block is executed whether or not an error occurs in the <code>try</code> block.</p>

    <h2>4. Common Error Types in JavaScript</h2>
    <ul>
        <li><strong>ReferenceError:</strong> Accessing a variable that hasn't been declared.</li>
        <li><strong>TypeError:</strong> Performing an operation on a value of an inappropriate type.</li>
        <li><strong>SyntaxError:</strong> Invalid JavaScript syntax.</li>
        <li><strong>RangeError:</strong> A number is outside the range of allowable values.</li>
    </ul>
    <h3>Example: Handling Specific Error Types</h3>
    <code>
try {
    let numbers = new Array(-1); // RangeError
} catch (error) {
    if (error instanceof RangeError) {
        console.error("RangeError:", error.message);
    } else {
        console.error("Other error:", error.message);
    }
}
/* Output:
RangeError: Invalid array length
*/
    </code>

    <h2>Summary</h2>
    <ul>
        <li>Use <code>try</code>-<code>catch</code> to handle errors gracefully and prevent the program from crashing.</li>
        <li>Throw errors when necessary to signal invalid conditions in your code.</li>
        <li>Use the <code>finally</code> block for cleanup actions that need to run regardless of success or failure.</li>
        <li>Handle specific error types for more robust error management.</li>
    </ul>
</body>
</html>
